<?xml version="1.0"?>

<robot name="SBR">

    <material name="dark_grey">
        <color rgba="0.4 0.4 0.4 1"/>
    </material>

    <material name="light_grey">
        <color rgba="0.9 0.9 0.9 1"/>
    </material>

    <link name="base_link">
        <visual>
            <geometry>
                <mesh filename="file:///home/drak/ros2_ws/src/cadtoURDF/meshes/base_link.STL"/>
            </geometry>

            <origin xyz="0 0 0.4" rpy="0 0 0"/>
            <material name="light_grey"/>
        </visual>
    </link>

    <link name="left_wheel">
        <visual>
            <geometry>
                <mesh filename="file:///home/drak/ros2_ws/src/cadtoURDF/meshes/left_wheel.STL"/>
            </geometry>

            <origin xyz="0 -0.70586 0" rpy="1.57 0 0"/>
            <material name="dark_grey"/>
        </visual>
    </link>

    <link name="right_wheel">
        <visual>
            <geometry>
                <mesh filename="file:///home/drak/ros2_ws/src/cadtoURDF/meshes/right_wheel.STL"/>
            </geometry>

            <origin xyz="0 0.70586 0" rpy="1.57 0 0"/>
            <material name="dark_grey"/>
        </visual>
    </link>

    <joint name="base_left_wheel_joint" type="continuous">
        <parent link="base_link"/>
        <child link="left_wheel"/>
        <origin xyz="0 0 0" rpy="0 0 0"/>
        <axis xyz="0 1 0"/>
    </joint>

    <joint name="base_right_wheel_joint" type="continuous">
        <parent link="base_link"/>
        <child link="right_wheel"/>
        <origin xyz="0 0 0" rpy="0 0 0"/>
        <axis xyz="0 1 0"/>
    </joint>

</robot>